2023-06-06 19:14:14,700 INFO    StreamThr :2304 [internal.py:wandb_internal():86] W&B internal server running at pid: 2304, started at: 2023-06-06 19:14:14.699934
2023-06-06 19:14:14,703 DEBUG   HandlerThread:2304 [handler.py:handle_request():144] handle_request: status
2023-06-06 19:14:14,706 INFO    WriterThread:2304 [datastore.py:open_for_write():85] open: /home/mlops_zoomcamp/mlops-zoomcamp/cohorts/2023/02-experiment-tracking/homework-wandb/wandb/run-20230606_191414-lv02oiwm/run-lv02oiwm.wandb
2023-06-06 19:14:14,707 DEBUG   SenderThread:2304 [sender.py:send():375] send: header
2023-06-06 19:14:14,718 DEBUG   SenderThread:2304 [sender.py:send():375] send: run
2023-06-06 19:14:14,863 ERROR   SenderThread:2304 [internal_api.py:execute():288] 404 response executing GraphQL.
2023-06-06 19:14:14,863 ERROR   SenderThread:2304 [internal_api.py:execute():289] {"errors":[{"message":"entity kushalm--raw_data_path not found during upsertBucket","path":["upsertBucket"]}],"data":{"upsertBucket":null}}
2023-06-06 19:14:14,863 ERROR   SenderThread:2304 [sender.py:send_run():979] It appears that you do not have permission to access the requested resource. Please reach out to the project owner to grant you access. If you have the correct permissions, verify that there are no issues with your networking setup.(Error 404: Not Found)
Traceback (most recent call last):
  File "/home/mlops_zoomcamp/anaconda3/envs/hw2/lib/python3.9/site-packages/wandb/sdk/lib/retry.py", line 131, in __call__
    result = self._call_fn(*args, **kwargs)
  File "/home/mlops_zoomcamp/anaconda3/envs/hw2/lib/python3.9/site-packages/wandb/sdk/internal/internal_api.py", line 285, in execute
    return self.client.execute(*args, **kwargs)  # type: ignore
  File "/home/mlops_zoomcamp/anaconda3/envs/hw2/lib/python3.9/site-packages/wandb/vendor/gql-0.2.0/wandb_gql/client.py", line 52, in execute
    result = self._get_result(document, *args, **kwargs)
  File "/home/mlops_zoomcamp/anaconda3/envs/hw2/lib/python3.9/site-packages/wandb/vendor/gql-0.2.0/wandb_gql/client.py", line 60, in _get_result
    return self.transport.execute(document, *args, **kwargs)
  File "/home/mlops_zoomcamp/anaconda3/envs/hw2/lib/python3.9/site-packages/wandb/sdk/lib/gql_request.py", line 56, in execute
    request.raise_for_status()
  File "/home/mlops_zoomcamp/anaconda3/envs/hw2/lib/python3.9/site-packages/requests/models.py", line 1021, in raise_for_status
    raise HTTPError(http_error_msg, response=self)
requests.exceptions.HTTPError: 404 Client Error: Not Found for url: https://api.wandb.ai/graphql

During handling of the above exception, another exception occurred:

Traceback (most recent call last):
  File "/home/mlops_zoomcamp/anaconda3/envs/hw2/lib/python3.9/site-packages/wandb/sdk/internal/sender.py", line 977, in send_run
    self._init_run(run, config_value_dict)
  File "/home/mlops_zoomcamp/anaconda3/envs/hw2/lib/python3.9/site-packages/wandb/sdk/internal/sender.py", line 1015, in _init_run
    server_run, inserted, server_messages = self._api.upsert_run(
  File "/home/mlops_zoomcamp/anaconda3/envs/hw2/lib/python3.9/site-packages/wandb/apis/normalize.py", line 73, in wrapper
    raise err
  File "/home/mlops_zoomcamp/anaconda3/envs/hw2/lib/python3.9/site-packages/wandb/apis/normalize.py", line 41, in wrapper
    return func(*args, **kwargs)
  File "/home/mlops_zoomcamp/anaconda3/envs/hw2/lib/python3.9/site-packages/wandb/sdk/internal/internal_api.py", line 1690, in upsert_run
    response = self.gql(
  File "/home/mlops_zoomcamp/anaconda3/envs/hw2/lib/python3.9/site-packages/wandb/sdk/internal/internal_api.py", line 257, in gql
    ret = self._retry_gql(
  File "/home/mlops_zoomcamp/anaconda3/envs/hw2/lib/python3.9/site-packages/wandb/sdk/lib/retry.py", line 147, in __call__
    retry_timedelta_triggered = check_retry_fn(e)
  File "/home/mlops_zoomcamp/anaconda3/envs/hw2/lib/python3.9/site-packages/wandb/util.py", line 907, in check_retry_fn
    return fallback_retry_fn(e)
  File "/home/mlops_zoomcamp/anaconda3/envs/hw2/lib/python3.9/site-packages/wandb/util.py", line 849, in no_retry_auth
    raise CommError(
wandb.errors.CommError: It appears that you do not have permission to access the requested resource. Please reach out to the project owner to grant you access. If you have the correct permissions, verify that there are no issues with your networking setup.(Error 404: Not Found)
2023-06-06 19:14:14,944 DEBUG   HandlerThread:2304 [handler.py:handle_request():144] handle_request: shutdown
2023-06-06 19:14:14,944 INFO    HandlerThread:2304 [handler.py:finish():842] shutting down handler
2023-06-06 19:14:15,718 INFO    WriterThread:2304 [datastore.py:close():298] close: /home/mlops_zoomcamp/mlops-zoomcamp/cohorts/2023/02-experiment-tracking/homework-wandb/wandb/run-20230606_191414-lv02oiwm/run-lv02oiwm.wandb
2023-06-06 19:14:15,872 INFO    SenderThread:2304 [sender.py:finish():1550] shutting down sender
